Workbook

Sheet Application Tracker
A1: QA Automation (Playwright/Cypress/Appium) — Hyderabad GCC Job Application Tracker
A2: Yellow = fill in as you apply. Orange rows = new 2025-2026 GCC entrants to Hyderabad (actively scaling — good application window).
A4: Company | B4: Sector | C4: HQ Country | D4: Year Arrived (Hyderabad) | E4: Role Applied For | F4: Portal/Source | G4: Date Applied | H4: Status | I4: Follow-up Date | J4: Recruiter/Contact | K4: Tech Stack Match | L4: Priority | M4: Notes
A5: Microsoft | B5: Technology | C5: USA | H5: Not Applied
A6: Google | B6: Technology | C6: USA | H6: Not Applied
A7: Amazon | B7: Technology | C7: USA | H7: Not Applied
A8: Apple | B8: Technology | C8: USA | H8: Not Applied
A9: Salesforce | B9: Technology | C9: USA | H9: Not Applied
A10: Meta | B10: Technology | C10: USA | H10: Not Applied
A11: Oracle | B11: Technology | C11: USA | H11: Not Applied
A12: ServiceNow | B12: Technology | C12: USA | D12: 2014 | H12: Not Applied
A13: IBM Software Labs | B13: Technology | C13: USA | H13: Not Applied
A14: Qualcomm | B14: Technology | C14: USA | H14: Not Applied
A15: Micron Technology | B15: Semiconductors | C15: USA | H15: Not Applied
A16: AT&T | B16: Telecom | C16: USA | H16: Not Applied
A17: T-Mobile | B17: Telecom | C17: USA | D17: 2026 (expansion) | H17: Not Applied
A18: Netflix | B18: Media/Tech | C18: USA | D18: 2025-26 (new hub) | H18: Not Applied
A19: Warner Bros. Discovery | B19: Media/Tech | C19: USA | H19: Not Applied
A20: DAZN | B20: Media/Sports Tech | C20: UK | D20: 2025 | H20: Not Applied
A21: JPMorgan Chase | B21: BFSI/Fintech | C21: USA | H21: Not Applied
A22: Wells Fargo | B22: BFSI/Fintech | C22: USA | H22: Not Applied
A23: Goldman Sachs | B23: BFSI/Fintech | C23: USA | H23: Not Applied
A24: Vanguard | B24: BFSI/Fintech | C24: USA | D24: 2025 (first India GCC) | H24: Not Applied | L24: High | M24: Live: QA Engineer (Automation/Manual/Mobile), 5+ yrs, Java, Appium, Selenium, API testing.
A25: State Street | B25: BFSI/Fintech | C25: USA | H25: Not Applied
A26: UBS | B26: BFSI/Fintech | C26: Switzerland | D26: 2026 (new site) | H26: Not Applied | L26: Medium | M26: Live: QA Engineer (Manual & Automation), Senior QA (Automation). Only ~7 roles in Hyderabad (more in Pune/Mumbai).
A27: HSBC | B27: BFSI/Fintech | C27: UK | H27: Not Applied
A28: Lloyds Banking Group | B28: BFSI/Fintech | C28: UK | H28: Not Applied
A29: Bank of America | B29: BFSI/Fintech | C29: USA | H29: Not Applied
A30: Chubb | B30: Insurance | C30: Switzerland/USA | H30: Not Applied
A31: Western Union | B31: Fintech | C31: USA | H31: Not Applied
A32: Novartis | B32: Pharma/Life Sciences | C32: Switzerland | H32: Not Applied
A33: Sanofi | B33: Pharma/Life Sciences | C33: France | D33: 2026 (major expansion) | H33: Not Applied
A34: Eli Lilly | B34: Pharma/Life Sciences | C34: USA | H34: Not Applied
A35: Bristol Myers Squibb | B35: Pharma/Life Sciences | C35: USA | D35: 2023 | H35: Not Applied
A36: Amgen | B36: Pharma/Life Sciences | C36: USA | D36: 2024 | H36: Not Applied
A37: UnitedHealth Group / Optum | B37: Healthcare | C37: USA | H37: Not Applied
A38: Elevance Health (Carelon) | B38: Healthcare | C38: USA | H38: Not Applied
A39: Cohere Health | B39: Healthcare | C39: USA | D39: 2025-26 (first intl. centre) | H39: Not Applied
A40: HCA Healthcare | B40: Healthcare | C40: USA | D40: 2025 ($75M first GCC) | H40: Not Applied | L40: High | M40: Live: Sr. SDET — Selenium (UI), Postman/Newman (API), Jenkins/GitHub Actions/Azure DevOps CI/CD.
A41: Abbott | B41: Healthcare | C41: USA | H41: Not Applied
...

Sheet Dashboard
A1: Application Tracker — Dashboard
A2: Auto-updates from 'Application Tracker' sheet. Do not edit formula cells.
A4: Status | B4: Count | D4: Sector | E4: Count
A5: Not Applied | B5: =COUNTIF('Application Tracker'!$H$5:$H$150,A5) -> 110 | D5: Aerospace | E5: =COUNTIF('Application Tracker'!$B$5:$B$150,D5) -> 1
A6: Applied | B6: =COUNTIF('Application Tracker'!$H$5:$H$150,A6) -> 0 | D6: Automotive | E6: =COUNTIF('Application Tracker'!$B$5:$B$150,D6) -> 1
A7: Screening | B7: =COUNTIF('Application Tracker'!$H$5:$H$150,A7) -> 0 | D7: Aviation | E7: =COUNTIF('Application Tracker'!$B$5:$B$150,D7) -> 2
A8: Interview Scheduled | B8: =COUNTIF('Application Tracker'!$H$5:$H$150,A8) -> 0 | D8: BFSI/Fintech | E8: =COUNTIF('Application Tracker'!$B$5:$B$150,D8) -> 14
A9: Interview Completed | B9: =COUNTIF('Application Tracker'!$H$5:$H$150,A9) -> 0 | D9: BFSI/Insurance | E9: =COUNTIF('Application Tracker'!$B$5:$B$150,D9) -> 3
A10: Offer | B10: =COUNTIF('Application Tracker'!$H$5:$H$150,A10) -> 0 | D10: BPO/Technology Services | E10: =COUNTIF('Application Tracker'!$B$5:$B$150,D10) -> 2
A11: Rejected | B11: =COUNTIF('Application Tracker'!$H$5:$H$150,A11) -> 0 | D11: Biopharma/CDMO | E11: =COUNTIF('Application Tracker'!$B$5:$B$150,D11) -> 1
A12: No Response | B12: =COUNTIF('Application Tracker'!$H$5:$H$150,A12) -> 0 | D12: Building Products Distribution | E12: =COUNTIF('Application Tracker'!$B$5:$B$150,D12) -> 1
A13: Withdrawn | B13: =COUNTIF('Application Tracker'!$H$5:$H$150,A13) -> 0 | D13: Chemicals | E13: =COUNTIF('Application Tracker'!$B$5:$B$150,D13) -> 1
A14: Total Companies Tracked | B14: =COUNTA('Application Tracker'!$A$5:$A$150) -> 102 | D14: Cybersecurity | E14: =COUNTIF('Application Tracker'!$B$5:$B$150,D14) -> 1
A15: New 2025-26 Entrants Tracked | B15: 48 | D15: Cybersecurity (MDR) | E15: =COUNTIF('Application Tracker'!$B$5:$B$150,D15) -> 1
D16: Cybersecurity/Tech | E16: =COUNTIF('Application Tracker'!$B$5:$B$150,D16) -> 2
D17: Data/Cloud Storage Tech | E17: =COUNTIF('Application Tracker'!$B$5:$B$150,D17) -> 1
D18: E-Commerce/Technology | E18: =COUNTIF('Application Tracker'!$B$5:$B$150,D18) -> 1
D19: Energy/Oil & Gas | E19: =COUNTIF('Application Tracker'!$B$5:$B$150,D19) -> 1
D20: Engineering/Industrial | E20: =COUNTIF('Application Tracker'!$B$5:$B$150,D20) -> 3
D21: Engineering/Tech | E21: =COUNTIF('Application Tracker'!$B$5:$B$150,D21) -> 1
D22: Environmental Services | E22: =COUNTIF('Application Tracker'!$B$5:$B$150,D22) -> 1
D23: Fintech | E23: =COUNTIF('Application Tracker'!$B$5:$B$150,D23) -> 2
D24: Fintech/Data | E24: =COUNTIF('Application Tracker'!$B$5:$B$150,D24) -> 1
D25: Food Services | E25: =COUNTIF('Application Tracker'!$B$5:$B$150,D25) -> 1
D26: Healthcare | E26: =COUNTIF('Application Tracker'!$B$5:$B$150,D26) -> 6
D27: Healthcare IT | E27: =COUNTIF('Application Tracker'!$B$5:$B$150,D27) -> 1
... D50: Travel Technology | E50: =COUNTIF('Application Tracker'!$B$5:$B$150,D50) -> 1

Sheet How to Use
A1: How to Use This Tracker
A3: Company / Sector / HQ Country | B3: Pre-filled with 70 verified Hyderabad GCC companies from research. Add more rows at the bottom for any company you find yourself.
A4: Year Arrived (Hyderabad) | B4: When known: the year the GCC was established or most recently expanded in Hyderabad. Blank = long-established, exact year not verified from public sources.
A5: Orange-highlighted rows | B5: Companies confirmed as new to Hyderabad in 2025-2026 (or a major recent expansion). These are actively scaling headcount right now -- often the best window to apply, since roles are opening faster than they can be filled.
A6: Role Applied For | B6: e.g. SDET, QA Automation Engineer, Senior QA Engineer -- copy from the job posting.
A7: Portal/Source | B7: Dropdown: Hirist, Instahyre, LinkedIn, Naukri, Foundit, Cutshort, myjobb, Arya, Company Website, Referral, Other.
A8: Date Applied | B8: Date you submitted the application.
A9: Status | B9: Dropdown: Not Applied -> Applied -> Screening -> Interview Scheduled -> Interview Completed -> Offer / Rejected / No Response / Withdrawn.
A10: Follow-up Date | B10: Set this ~7-10 days after applying; check the Dashboard weekly to see what's due.
A11: Recruiter/Contact | B11: Name + email/LinkedIn of recruiter or referral contact, if you have one.
A12: Tech Stack Match | B12: Note which of your skills matched: Playwright, Cypress, Appium, TypeScript, CI/CD, etc. Helps you see which stack is landing interviews.
A13: Priority | B13: Dropdown: High / Medium / Low -- rank based on fit and interest so you know where to focus follow-ups.
A14: Notes | B14: Anything else -- interview feedback, salary range discussed, referral source, etc.
A15: Dashboard tab | B15: Auto-counts applications by Status and by Sector, plus a running count of new 2025-26 entrants. Updates automatically -- don't edit its formula cells directly.
